Workbook

Sheet Overview
A1: FIN 5637 CLASSWORK EXIT ANALYSIS WEEK 3
A2: RPG Corp.
A3: EXIT ANALYSIS

Sheet Transaction
A1: TRANSACTION
A2: RPG CORP.
A3: $ in millions | E3: EBITDA | F3: =Financials!C20+Financials!C17 -> 625
E4: Multiple | F4: 8
E5: Purchase Price | F5: =F3*F4 -> 5000
B6: Sources | E6: Amount | F6: % of Total
B7: Equity | E7: 1775 | F7: =E7/$E$10 -> 0.35323383
B8: Term Debt | E8: 2000 | F8: =E8/$E$10 -> 0.39800995
B9: Subordinated Notes | E9: 1250 | F9: =E9/$E$10 -> 0.24875622
B10: Total Sources | E10: =SUM(E7:E9) -> 5025 | F10: =SUM(F7:F9) -> 1
B12: Uses | E12: Amount | F12: % of Total
B13: Purchase Price | E13: =F5 -> 5000 | F13: =E13/$E$15 -> 0.99502488
B14: Transaction Expenses | E14: 25 | F14: =E14/$E$15 -> 0.0049751244
B15: Total Uses | E15: =SUM(E13:E14) -> 5025 | F15: =SUM(F13:F14) -> 1

Sheet Financials
A1: PROJECTIONS
A2: =Overview!A2 -> RPG Corp.
A3: $ in millions
C5: Year 1 | D5: Year 2 | E5: Year 3 | F5: Year 4 | G5: Year 5 | H5: Year 6
A7: Revenue | C7: 2625 | D7: 2756.25 | E7: 2907.8438 | F7: 3089.584 | G7: 3267.2351 | H7: 3414.2606
A8: Growth Rate | C8: — | D8: =IFERROR((D7-C7)/C7,"—") -> 0.05 | E8: =IFERROR((E7-D7)/D7,"—") -> 0.055 | F8: =IFERROR((F7-E7)/E7,"—") -> 0.0625 | G8: =IFERROR((G7-F7)/F7,"—") -> 0.0575 | H8: =IFERROR((H7-G7)/G7,"—") -> 0.045
A10: Cost of Goods Sold | C10: 1753.8 | D10: 1842 | E10: 1935.8 | F10: 2035.4 | G10: 2148.8 | H10: 2235.4
A12: Gross Profit | C12: =C7-C10 -> 871.2 | D12: =D7-D10 -> 914.25 | E12: =E7-E10 -> 972.04375 | F12: =F7-F10 -> 1054.184 | G12: =G7-G10 -> 1118.4351 | H12: =H7-H10 -> 1178.8606
A13: Gross Profit Margin | C13: =IFERROR(C12/C7,"—") -> 0.33188571 | D13: =IFERROR(D12/D7,"—") -> 0.33170068 | E13: =IFERROR(E12/E7,"—") -> 0.33428335 | F13: =IFERROR(F12/F7,"—") -> 0.3412058 | G13: =IFERROR(G12/G7,"—") -> 0.34231852 | H13: =IFERROR(H12/H7,"—") -> 0.34527553
A15: Selling and Marketing Expenses | C15: 144.4 | D15: 151.59375 | E15: 159.93141 | F15: 169.92712 | G15: 179.69793 | H15: 195.2
A16: General and Administrative | C16: 101.8 | D16: 104.4 | E16: 108.5 | F16: 113.4 | G16: 118.2 | H16: 122.5
A17: Depreciation and Amortization | C17: 105.5 | D17: 113.00625 | E17: 119.22159 | F17: 126.67294 | G17: 133.95664 | H17: 139.98469
A18: Total Expenses | C18: =SUM(C15:C17) -> 351.7 | D18: =SUM(D15:D17) -> 369 | E18: =SUM(E15:E17) -> 387.653 | F18: =SUM(F15:F17) -> 410.00006 | G18: =SUM(G15:G17) -> 431.85457 | H18: =SUM(H15:H17) -> 457.68469
A20: EBIT | C20: =C12-C18 -> 519.5 | D20: =D12-D18 -> 545.25 | E20: =E12-E18 -> 584.39075 | F20: =F12-F18 -> 644.18392 | G20: =G12-G18 -> 686.5805 | H20: =H12-H18 -> 721.17596
A21: EBIT Margin | C21: =IFERROR(C20/C7,"—") -> 0.19790476 | D21: =IFERROR(D20/D7,"—") -> 0.19782313 | E21: =IFERROR(E20/E7,"—") -> 0.20097048 | F21: =IFERROR(F20/F7,"—") -> 0.20850183 | G21: =IFERROR(G20/G7,"—") -> 0.21014114 | H21: =IFERROR(H20/H7,"—") -> 0.21122463
A23: Debt Schedule | B23: Beginning Balance
A24: Term Loan | B24: 2000
A25: Principal Payment Rate | B25: 0.1 | C25: =$B$25*$B$24 -> 200 | D25: =$B$25*$B$24 -> 200 | E25: =$B$25*$B$24 -> 200 | F25: =$B$25*$B$24 -> 200 | G25: =$B$25*$B$24 -> 200 | H25: =$B$25*$B$24 -> 200
A26: Ending Balance | C26: =$B$24-C25 -> 1800 | D26: =C26-D25 -> 1600 | E26: =D26-E25 -> 1400 | F26: =E26-F25 -> 1200 | G26: =F26-G25 -> 1000 | H26: =G26-H25 -> 800
A28: Subordinated Notes | B28: 1250 | C28: =B28 -> 1250 | D28: =C28 -> 1250 | E28: =D28 -> 1250 | F28: =E28 -> 1250 | G28: =F28 -> 1250 | H28: =G28 -> 1250
A30: Total Debt Outstanding | B30: =B24+B28 -> 3250 | C30: =C26+C28 -> 3050 | D30: =D26+D28 -> 2850 | E30: =E26+E28 -> 2650 | F30: =F26+F28 -> 2450 | G30: =G26+G28 -> 2250 | H30: =H26+H28 -> 2050

Sheet Exit Analysis
A1: EXIT ANALYSIS
A2: =Financials!A2 -> RPG Corp.
A3: $ in millions
A5: KEY ASSUMPTIONS | D5: Year 4 | E5: Year 5 | F5: Year 6
A6: Years Until Exit | D6: 4 | E6: 5 | F6: 6
A7: Target Return (Hurdle Rate) | D7: 0.25 | E7: 0.25 | F7: 0.25
A8: Management Interest (if hurdle met) | D8: 0.05 | E8: 0.05 | F8: 0.05
A9: EBITDA at Exit | D9: =Financials!F20+Financials!F17 -> 770.85687 | E9: =Financials!G20+Financials!G17 -> 820.53713 | F9: =Financials!H20+Financials!H17 -> 861.16064
A11: ENTERPRISE VALUE AT EXIT | B11: Exit Multiple
B12: 8 | D12: =$B12*D$9 -> 6166.8549 | E12: =$B12*E$9 -> 6564.2971 | F12: =$B12*F$9 -> 6889.2851
B13: 9 | D13: =$B13*D$9 -> 6937.7118 | E13: =$B13*E$9 -> 7384.8342 | F13: =$B13*F$9 -> 7750.4458
B14: 10 | D14: =$B14*D$9 -> 7708.5687 | E14: =$B14*E$9 -> 8205.3713 | F14: =$B14*F$9 -> 8611.6064
B15: 11 | D15: =$B15*D$9 -> 8479.4255 | E15: =$B15*E$9 -> 9025.9085 | F15: =$B15*F$9 -> 9472.7671
A17: Debt Outstanding at Exit | D17: =Financials!F30 -> 2450 | E17: =Financials!G30 -> 2250 | F17: =Financials!H30 -> 2050
A18: (No cash add-back assumed)
A20: EQUITY VALUE AT EXIT | B20: Exit Multiple
B21: =$B$12 -> 8 | D21: =D12-D$17 -> 3716.8549 | E21: =E12-E$17 -> 4314.2971 | F21: =F12-F$17 -> 4839.2851
B22: =$B$13 -> 9 | D22: =D13-D$17 -> 4487.7118 | E22: =E13-E$17 -> 5134.8342 | F22: =F13-F$17 -> 5700.4458
B23: =$B$14 -> 10 | D23: =D14-D$17 -> 5258.5687 | E23: =E14-E$17 -> 5955.3713 | F23: =F14-F$17 -> 6561.6064
B24: =$B$15 -> 11 | D24: =D15-D$17 -> 6029.4255 | E24: =E15-E$17 -> 6775.9085 | F24: =F15-F$17 -> 7422.7671
A26: Initial Equity Investment | D26: =Transaction!E7 -> 1775 | E26: =D26 -> 1775 | F26: =D26 -> 1775
A29: GROSS IRR (Pre-Mgmt) | B29: Exit Multiple
B30: =$B$12 -> 8 | D30: =IFERROR(RATE(D$6,0,-D$26,D21),"N/A") -> 0.20294096 | E30: =IFERROR(RATE(E$6,0,-E$26,E21),"N/A") -> 0.19437949 | F30: =IFERROR(RATE(F$6,0,-F$26,F21),"N/A") -> 0.18194466
B31: =$B$13 -> 9 | D31: =IFERROR(RATE(D$6,0,-D$26,D22),"N/A") -> 0.2609755 | E31: =IFERROR(RATE(E$6,0,-E$26,E22),"N/A") -> 0.23670357 | F31: =IFERROR(RATE(F$6,0,-F$26,F22),"N/A") -> 0.21465165
B32: =$B$14 -> 10 | D32: =IFERROR(RATE(D$6,0,-D$26,D23),"N/A") -> 0.31195004 | E32: =IFERROR(RATE(E$6,0,-E$26,E23),"N/A") -> 0.27391983 | F32: =IFERROR(RATE(F$6,0,-F$26,F23),"N/A") -> 0.24346997
B33: =$B$15 -> 11 | D33: =IFERROR(RATE(D$6,0,-D$26,D24),"N/A") -> 0.35759239 | E33: =IFERROR(RATE(E$6,0,-E$26,E24),"N/A") -> 0.3072355 | F33: =IFERROR(RATE(F$6,0,-F$26,F24),"N/A") -> 0.26929113
A35: Target Achieved?
A37: HURDLE ACHIEVED? | B37: Exit Multiple
B38: =$B$12 -> 8 | D38: =IF(D30>=D$7,"Yes","No") -> No | E38: =IF(E30>=E$7,"Yes","No") -> No | F38: =IF(F30>=F$7,"Yes","No") -> No
B39: =$B$13 -> 9 | D39: =IF(D31>=D$7,"Yes","No") -> Yes | E39: =IF(E31>=E$7,"Yes","No") -> No | F39: =IF(F31>=F$7,"Yes","No") -> No
B40: =$B$14 -> 10 | D40: =IF(D32>=D$7,"Yes","No") -> Yes | E40: =IF(E32>=E$7,"Yes","No") -> Yes | F40: =IF(F32>=F$7,"Yes","No") -> No
B41: =$B$15 -> 11 | D41: =IF(D33>=D$7,"Yes","No") -> Yes | E41: =IF(E33>=E$7,"Yes","No") -> Yes | F41: =IF(F33>=F$7,"Yes","No") -> Yes
A43: BAIN OWNERSHIP % | B43: Exit Multiple
B44: =$B$12 -> 8 | D44: =IF(D38="Yes",1-D$8,1) -> 1 | E44: =IF(E38="Yes",1-E$8,1) -> 1 | F44: =IF(F38="Yes",1-F$8,1) -> 1
B45: =$B$13 -> 9 | D45: =IF(D39="Yes",1-D$8,1) -> 0.95 | E45: =IF(E39="Yes",1-E$8,1) -> 1 | F45: =IF(F39="Yes",1-F$8,1) -> 1
B46: =$B$14 -> 10 | D46: =IF(D40="Yes",1-D$8,1) -> 0.95 | E46: =IF(E40="Yes",1-E$8,1) -> 0.95 | F46: =IF(F40="Yes",1-F$8,1) -> 1
B47: =$B$15 -> 11 | D47: =IF(D41="Yes",1-D$8,1) -> 0.95 | E47: =IF(E41="Yes",1-E$8,1) -> 0.95 | F47: =IF(F41="Yes",1-F$8,1) -> 0.95
A49: BAIN EQUITY VALUE | B49: Exit Multiple
B50: =$B$12 -> 8 | D50: =D44*D21 -> 3716.8549 | E50: =E44*E21 -> 4314.2971 | F50: =F44*F21 -> 4839.2851
B51: =$B$13 -> 9 | D51: =D45*D22 -> 4263.3262 | E51: =E45*E22 -> 5134.8342 | F51: =F45*F22 -> 5700.4458
...
